<?xml version='1.0' encoding='utf-8'?>
<mujoco model="typea">
  <compiler angle="radian" meshdir="meshes" coordinate="local" />
  <worldbody>
    <geom mesh="916d31db_Bioloid_CUERPO_vis_4" type="mesh" pos="0 0 0" euler="0 0 0" class="visual" />
    <geom mesh="94afeb60_BPF-CHEST-B_FCD-Conv_BDR-Col" type="mesh" pos="0 0 0" euler="0 1.5708 1.5708" class="visual" />
    <geom mesh="8b120736_BPF-CHEST-F_FCD-Conv_BDR-Col" type="mesh" pos="0 0 0" euler="0 1.5708 1.5708" class="visual" />
    <geom mesh="df1d2ef7_CM-5_FCD-Conv_BDR-Col" type="mesh" pos="-0.032 0 -0.015" euler="3.141592653589793 0 1.5707963267948966" class="visual" />
    <!--geom mesh="2c813877_AX-S1_FCD-Conv_BDR-Col" type="mesh" pos="0 0 0.025" euler="0 -1.5707963267948966 -1.5707963267948966" class="visual" /-->
    <!--geom mesh="3c0b5d99_AX-12_FCD-Conv_BDR-Col" type="mesh" pos="0 -0.032 0" euler="0 1.5707963267948966 0" class="visual" /-->
    <geom mesh="d8612dc6_FP04-F3_FCD-Conv_BDR-Col" type="mesh" pos="-0.019 -0.032 -0.0145" euler="-1.57 3.141592653589793 1.5707963267948966" class="visual" />
    <!--geom mesh="3c0b5d99_AX-12_FCD-Conv_BDR-Col" type="mesh" pos="0 0.032 0"  euler="0 1.5707 1.5707963267948966" class="visual" /-->
    <geom mesh="d8612dc6_FP04-F3_FCD-Conv_BDR-Col" type="mesh" pos="-0.019 0.032 -0.0145" euler="-1.5707 3.141592653589793 1.5707963267948966" class="visual" />
    <geom mesh="d8612dc6_FP04-F3_FCD-Conv_BDR-Col" type="mesh" pos="0.0175 0 -0.0655" euler="0 0 1.5707963267948966" class="visual" />
    <geom mesh="d8612dc6_FP04-F3_FCD-Conv_BDR-Col" type="mesh" pos="-0.0175 0 -0.0655" euler="0 0 -1.5707963267948966" class="visual" />
    <geom mesh="3c0b5d99_AX-12_FCD-Conv_BDR-Col" type="mesh" pos="0 -0.0385 -0.0655" euler="0 3.1415 3.1415" class="visual" />
    <geom mesh="3c0b5d99_AX-12_FCD-Conv_BDR-Col" type="mesh" pos="0 0.0385 -0.0655" euler="0 3.1415 0" class="visual" />
    <geom name="head_collision" size="0.027 0.0165 0.022" pos="-0.0122 0 0.035" type="box" rgba="0.2 0.2 0.2 0.1" group="2" />
    <geom name="torso_collision_top" size="0.04525 0.0515 0.03175" pos="-0.019 0 -0.015" type="box" rgba="0.2 0.2 0.2 0.1" group="2" />
    <geom name="torso_collision_bottom" size="0.0325 0.0495 0.0215" pos="-0.00625 0 -0.0648" type="box" rgba="0.2 0.2 0.2 0.1" group="2" />
    <geom size="0.025 0.025 0.025" type="box" rgba="0.2 0.2 0.2 0.1" group="2" />
    <geom name="head2_collision" size="0.02 0.05 0.04" type="box" rgba="0.2 0.2 0.2 0.1" group="2" />
    <geom size="0.005 0.005 0.005" pos="0 0 0.05" type="box" rgba="0.2 0.2 0.2 0.1" group="2" />
    <body name="r_shoulder_swing_link" pos="0 -0.032 0" quat="0.5 0.5 0.5 -0.5">
      <geom mesh="11c5acbd_FP04-F1_FCD-Conv_BDR-Col" type="mesh" pos="0 0.014 0.044" euler="0 3.14159 3.14159" class="visual" />
      <inertial pos="0 0.006 0.0375" quat="0 0.707107 0 0.707107" mass="0.01" diaginertia="3.52e-06 3.33e-06 2.35e-06" />
      <joint name="r_shoulder_swing_joint" pos="0 0 0" axis="0 0 1" range="-1 1.5708" actuatorfrcrange="-2.8 2.8" />
      <geom name="r_shoulder_collision" size="0.026 0.0195 0.018" pos="0 0.006 0.0375" type="box" rgba="0.2 0.2 0.2 0.1" group="2" />
      <body name="r_upper_arm_link" pos="0 0.014 0.044" quat="0.707107 0 -0.707107 0">
        <geom mesh="3c0b5d99_AX-12_FCD-Conv_BDR-Col" type="mesh" pos="0 0 0" euler="0 0 1.5708" class="visual" />
        <geom mesh="5f501081_BPF-BU_FCD-Conv_BDR-Col" type="mesh" pos="0 0 -0.01850" euler="0 -1.5708 1.5708" class="visual" />
        <geom mesh="c9bc5e6a_BPF-WA_FCD-Conv_BDR-Col" type="mesh" pos="0 0 -0.019" euler="0 -1.5708 1.5708" class="visual" />
        <geom mesh="d8612dc6_FP04-F3_FCD-Conv_BDR-Col" type="mesh" pos="0.0415 0 0" euler="0 0 1.5708" class="visual" />
        <geom mesh="b04d8bdf_FP04-F2_FCD-Conv_BDR-Col" type="mesh" pos="0.0675 0 0" euler="1.5708 -1.5708 1.5708" class="visual" />
        <inertial pos="0.03536 0 0" quat="0.5 0.5 0.5 0.5" mass="0.07" diaginertia="5.746e-05 5.024e-05 1.99e-05" />
        <joint name="r_shoulder_lateral_joint" pos="0 0 0" axis="0 0 -1" range="-1.5 1.5" actuatorfrcrange="-2.8 2.8" />
        <geom name="r_upper arm_collision_proximal" size="0.027 0.0165 0.022" pos="0.0148 0 0" type="box" rgba="0.2 0.2 0.2 0.1" group="2" />
        <geom name="r_upper arm_collision_distal" size="0.0235 0.0165 0.026" pos="0.0555 0 0" type="box" rgba="0.2 0.2 0.2 0.1" group="2" />
        <body name="r_lower_arm_link" pos="0.0675 0 0">
          <geom mesh="3c0b5d99_AX-12_FCD-Conv_BDR-Col" type="mesh" pos="0 0 0" euler="0 0 1.5708" class="visual" />
          <geom mesh="5f501081_BPF-BU_FCD-Conv_BDR-Col" type="mesh" pos="0 0 0.0185" euler="0 1.5708 1.5708" class="visual" />
          <geom mesh="c9bc5e6a_BPF-WA_FCD-Conv_BDR-Col" type="mesh" pos="0 0 0.019" euler="0 1.5708 1.5708" class="visual" />
          <geom mesh="d8612dc6_FP04-F3_FCD-Conv_BDR-Col" type="mesh" pos="0.0415 0 0" euler="0 3.1416 -1.5708" class="visual" />
          <inertial pos="0.00554868 -0.0067729 -0.000515957" quat="0.479854 0.473689 0.522751 0.521624" mass="0.068" diaginertia="7.12121e-05 6.73943e-05 1.78853e-05" />
          <joint name="r_elbow_joint" pos="0 0 0" axis="0 0 -1" range="-1.77 1.77" actuatorfrcrange="-2.8 2.8" />
          <geom name="r_lower_arm_collision" size="0.029 0.0165 0.022" pos="0.017 0 0" type="box" rgba="0.2 0.2 0.2 0.1" group="2" />
          <body name="r_hand_link" pos="0.03 0 0">
            <geom mesh="abc2df66_FP04-F11_FCD-Conv_BDR-Col" type="mesh" pos="0 0 0" euler="-3.14 01.57 0" class="visual" />
            <!--inertial pos="0.00554868 -0.0067729 -0.000515957" quat="0.479854 0.473689 0.522751 0.521624" mass="0.008" diaginertia="7.12121e-05 6.773943e-05 1.78853e-05" />
            <joint name="r_hand_joint" pos="0 0 0" axis="0 0 0" /-->
            <geom name="r_palm_collision" size="0.00655 0.01325 0.022" pos="0.039 0 0" type="box" rgba="0.2 0.2 0.2 0.1" group="2" />
            <geom name="r_fingers_collision" size="0.02875 0.00875 0.0175" pos="0.0701 -0.0077 0" type="box" rgba="0.2 0.2 0.2 0.1" group="2" />
          </body>        
        </body>
      </body>
    </body>
    <body name="l_shoulder_swing_link" pos="0 0.032 0" quat="0.5 -0.5 -0.5 -0.5">
      <geom mesh="11c5acbd_FP04-F1_FCD-Conv_BDR-Col" type="mesh" pos="0 0.014 0.044" euler="0 3.14159 3.14159" class="visual" />
      <inertial pos="0 0.006 0.0375" quat="0 0.707107 0 0.707107" mass="0.01" diaginertia="3.52e-06 3.33e-06 2.35e-06" />
      <joint name="l_shoulder_swing_joint" pos="0 0 0" axis="0 0 1" range="-1 1.5708" actuatorfrcrange="-2.8 2.8" />
      <geom name="l_shoulder_collision" size="0.026 0.0195 0.018" pos="0 0.006 0.0375" type="box" rgba="0.2 0.2 0.2 0.1" group="2" />
      <body name="l_upper_arm_link" pos="0 0.014 0.044" quat="0.707107 0 -0.707107 0">
        <geom mesh="3c0b5d99_AX-12_FCD-Conv_BDR-Col" type="mesh" pos="0 0 0" euler="0 3.14159 -1.5708" class="visual" />
        <geom mesh="5f501081_BPF-BU_FCD-Conv_BDR-Col" type="mesh" pos="0 0 0.01850" euler="0 1.5708 1.5708" class="visual" />
        <geom mesh="c9bc5e6a_BPF-WA_FCD-Conv_BDR-Col" type="mesh" pos="0 0 0.019" euler="0 1.5708 1.5708" class="visual" />
        <geom mesh="d8612dc6_FP04-F3_FCD-Conv_BDR-Col" type="mesh" pos="0.0415 0 0" euler="3.14 0 1.5708" class="visual" />
        <geom mesh="b04d8bdf_FP04-F2_FCD-Conv_BDR-Col" type="mesh" pos="0.0675 0 0" euler="1.5708 -1.5708 1.5708" class="visual" />
        <inertial pos="0.03536 0 0" quat="0.5 0.5 0.5 0.5" mass="0.07" diaginertia="5.746e-05 5.024e-05 1.99e-05" />
        <joint name="l_shoulder_lateral_joint" pos="0 0 0" axis="0 0 1" range="-1.5 1.5" actuatorfrcrange="-2.8 2.8" />
        <geom name="l_upper arm_collision_proximal" size="0.027 0.0165 0.022" pos="0.0148 0 0" type="box" rgba="0.2 0.2 0.2 0.1" group="2" />
        <geom name="l_upper arm_collision_distal" size="0.0235 0.0165 0.026" pos="0.0555 0 0" type="box" rgba="0.2 0.2 0.2 0.1" group="2" />
        <body name="l_lower_arm_link" pos="0.0675 0 0">
          <geom mesh="3c0b5d99_AX-12_FCD-Conv_BDR-Col" type="mesh" pos="0 0 0" euler="0 3.14159 -1.5708" class="visual" />
          <geom mesh="5f501081_BPF-BU_FCD-Conv_BDR-Col" type="mesh" pos="0 0 0.0185" euler="-1.5708 3.14 -1.5708" class="visual" />
          <geom mesh="c9bc5e6a_BPF-WA_FCD-Conv_BDR-Col" type="mesh" pos="0 0 0.019" euler="-1.5708 3.14 -1.5708" class="visual" />
          <geom mesh="d8612dc6_FP04-F3_FCD-Conv_BDR-Col" type="mesh" pos="0.0415 0 0" euler="0 3.14 -1.5708" class="visual" />
          <inertial pos="0.00641783 0.00557279 -0.000592108" quat="0.519286 0.520103 0.476239 0.482733" mass="0.068" diaginertia="7.03478e-05 6.6411e-05 1.77672e-05" />
          <joint name="l_elbow_joint" pos="0 0 0" axis="0 0 1" range="-1.77 1.77" actuatorfrcrange="-2.8 2.8" />
          <geom name="l_lower_arm_collision" size="0.029 0.0165 0.022" pos="0.017 0 0" type="box" rgba="0.2 0.2 0.2 0.1" group="2" />
          <body name="l_hand_link" pos="0 0 0">
            <geom mesh="abc2df66_FP04-F11_FCD-Conv_BDR-Col" type="mesh" pos="0.0415 0 0" euler="-3.14 1.57 0" class="visual" />
            <geom name="l_palm_collision" size="0.00655 0.01325 0.022" pos="0.039 0 0" type="box" rgba="0.2 0.2 0.2 0.1" group="2" />
            <geom name="l_fingers_collision" size="0.02875 0.00875 0.0175" pos="0.0701 -0.0077 0" type="box" rgba="0.2 0.2 0.2 0.1" group="2" />
          </body>  
        </body>
      </body>
    </body>
    <body name="r_hip_twist_link" pos="0 -0.0385 -0.0655" quat="0 -0.383885 0.923381 0">
      <geom mesh="df207a8e_FP04-F5_FCD-Conv_BDR-Col" type="mesh" pos="0 0.02 0.05" euler="3.14159 0 3.14159" class="visual" />
      <inertial pos="0.0008 0.02 0.041" quat="0.707107 0.707107 0 0" mass="0.016" diaginertia="1.1372e-05 1.0307e-05 3.3083e-06" />
      <joint name="r_hip_twist_joint" pos="0 0 0" axis="0 0 1" range="-0.8 0.8" actuatorfrcrange="-10 10" />
      <geom name="r_hip_twist_collision" size="0.0145 0.0415 0.02025" pos="0.0008 0.02 0.041" type="box" rgba="0.2 0.2 0.2 0.1" group="2" />
      <body name="r_hip_lateral_link" pos="0 0 0.05" quat="0.707107 -0.707107 0 0">
        <inertial pos="0 -0.0135 0.02" mass="0.12" diaginertia="7.79941e-05 6.79841e-05 4.20099e-05" />
        <joint name="r_hip_lateral_joint" pos="0 0 0" axis="0 0 -1" range="-0.8 0.8" actuatorfrcrange="-10 10" />
        <geom name="r_hip_lateral_collision" size="0.02 0.0255 0.03605" pos="0 -0.0135 0.02" type="box" rgba="0.2 0.2 0.2 0.1" group="2" />
        <body name="r_upper_leg_link" quat="0.5 0.5 -0.5 -0.5">
          <inertial pos="0.0413221 0.00280897 0" quat="0.472541 0.472541 0.526028 0.526028" mass="0.03" diaginertia="2.96116e-05 2.64478e-05 8.84124e-06" />
          <joint name="r_hip_swing_joint" pos="0 0 0" axis="0 0 1" range="-2 2" actuatorfrcrange="-10 10" />
          <geom name="r_upper_leg_proximal_collision" size="0.0325 0.015 0.0245" pos="0.0214 0 0" type="box" rgba="0.2 0.2 0.2 0.1" group="2" />
          <geom name="r_upper_leg_distal_collision" size="0.02 0.01855 0.0245" pos="0.0675 0.0065 0" type="box" rgba="0.2 0.2 0.2 0.1" group="2" />
          <body name="r_lower_leg_link" pos="0.075 0.0145 0">
            <inertial pos="0.0280842 -0.0140708 0" quat="0.504228 0.504228 0.495736 0.495736" mass="0.08" diaginertia="8.23327e-05 7.85267e-05 2.55464e-05" />
            <joint name="r_knee_joint" pos="0 0 0" axis="0 0 -1" range="-2 0" actuatorfrcrange="-10 10" />
            <geom name="r_lower_leg_proximal_collision" size="0.0165 0.0255 0.022" pos="0 -0.0135 0" type="box" rgba="0.2 0.2 0.2 0.1" group="2" />
            <geom name="r_lower_leg_distal_collision" size="0.0335 0.015 0.0245" pos="0.0492 -0.0145 0" type="box" rgba="0.2 0.2 0.2 0.1" group="2" />
            <body name="r_ankle_swing_link" pos="0.071 -0.0145 0" quat="0 1 0 0">
              <inertial pos="-0.0135 -0.0167 0" quat="0.5 0.5 -0.5 0.5" mass="0.0685" diaginertia="4.45216e-05 3.88076e-05 2.39807e-05" />
              <joint name="r_ankle_swing_joint" pos="0 0 0" axis="0 0 1" range="-0.4 2" actuatorfrcrange="-10 10" />
              <geom name="r_ankle_swing_collision" size="0.0255 0.03605 0.02" pos="-0.0135 -0.0167 0" type="box" rgba="0.2 0.2 0.2 0.1" group="2" />
              <body name="r_ankle_lateral_link" quat="0.707107 -0.707107 0 0">
                <inertial pos="0.0110662 0.00171994 0.00142326" quat="0.778579 -0.0363424 -0.0287513 0.625833" mass="0.03" diaginertia="3.27142e-05 2.73521e-05 1.67953e-05" />
                <joint name="r_ankle_lateral_joint" pos="0 0 0" axis="0 0 -1" range="-0.8 0.8" actuatorfrcrange="-10 10" />
                <geom name="r_ankle_lateral_collision" size="0.02025 0.0145 0.0415" pos="0.009 0 -0.016" type="box" rgba="0.2 0.2 0.2 0.1" group="2" />
                <geom name="r_foot_collision" size="0.0045 0.0305 0.0505" pos="0.0277 0 0" type="box" rgba="0.2 0.2 0.2 0.1" group="2" />
              </body>
            </body>
          </body>
        </body>
      </body>
    </body>
    <body name="l_hip_twist_link" pos="0 0.0385 -0.0655" quat="0 0.383885 0.923381 0">
      <geom mesh="df207a8e_FP04-F5_FCD-Conv_BDR-Col" type="mesh" pos="0 -0.02 0.05" euler="3.14159 0 0" class="visual" />
      <inertial pos="0.0008 -0.02 0.041" quat="0.707107 0.707107 0 0" mass="0.016" diaginertia="1.1372e-05 1.0307e-05 3.3083e-06" />
      <joint name="l_hip_twist_joint" pos="0 0 0" axis="0 0 1" range="-0.8 0.8" actuatorfrcrange="-10 10" />
      <geom name="l_hip_twist_collision" size="0.0145 0.0415 0.02025" pos="0.0008 -0.02 0.041" type="box" rgba="0.2 0.2 0.2 0.1" group="2" />
      <body name="l_hip_lateral_link" pos="0 0 0.05" quat="0.707107 0.707107 0 0">
        <inertial pos="0 0.0135 0.02" mass="0.12" diaginertia="7.7994e-05 6.7984e-05 4.20099e-05" />
        <joint name="l_hip_lateral_joint" pos="0 0 0" axis="0 0 -1" range="-0.8 0.8" actuatorfrcrange="-10 10" />
        <geom name="l_hip_lateral_collision" size="0.02 0.0255 0.03605" pos="0 0.0135 0.02" type="box" rgba="0.2 0.2 0.2 0.1" group="2" />
        <body name="l_upper_leg_link" quat="0.5 0.5 -0.5 -0.5">
          <inertial pos="-0.0413221 0.00280897 0" quat="0.526028 0.526028 0.472541 0.472541" mass="0.03" diaginertia="2.96116e-05 2.64478e-05 8.84124e-06" />
          <joint name="l_hip_swing_joint" pos="0 0 0" axis="0 0 1" range="-2 2" actuatorfrcrange="-10 10" />
          <geom name="l_upper_leg_proximal_collision" size="0.0325 0.015 0.0245" pos="-0.0214 0 0" type="box" rgba="0.2 0.2 0.2 0.1" group="2" />
          <geom name="l_upper_leg_distal_collision" size="0.02 0.01855 0.0245" pos="-0.0675 0.0065 0" type="box" rgba="0.2 0.2 0.2 0.1" group="2" />
          <body name="l_lower_leg_link" pos="-0.075 0.0145 0">
            <inertial pos="-0.0280842 -0.0140708 0" quat="0.495736 0.495736 0.504228 0.504228" mass="0.08" diaginertia="8.23324e-05 7.8527e-05 2.55466e-05" />
            <joint name="l_knee_joint" pos="0 0 0" axis="0 0 -1" range="0 2" actuatorfrcrange="-10 10" />
            <geom name="l_lower_leg_proximal_collision" size="0.0165 0.0255 0.022" pos="0 -0.0135 0" type="box" rgba="0.2 0.2 0.2 0.1" group="2" />
            <geom name="l_lower_leg_distal_collision" size="0.0335 0.015 0.0245" pos="-0.0492 -0.0145 0" type="box" rgba="0.2 0.2 0.2 0.1" group="2" />
            <body name="l_ankle_swing_link" pos="-0.071 -0.0145 0" quat="0 1 0 0">
              <inertial pos="0.0135 -0.0167 0" quat="0.5 0.5 -0.5 0.5" mass="0.0685" diaginertia="4.45216e-05 3.88076e-05 2.39807e-05" />
              <joint name="l_ankle_swing_joint" pos="0 0 0" axis="0 0 1" range="-2 0.4" actuatorfrcrange="-10 10" />
              <geom name="l_ankle_swing_collision" size="0.0255 0.03605 0.02" pos="0.0135 -0.0167 0" type="box" rgba="0.2 0.2 0.2 0.1" group="2" />
              <body name="l_ankle_lateral_link" quat="0.707107 -0.707107 0 0">
                <inertial pos="-0.0166338 -0.00175072 0.00142326" quat="0.868957 0.0102562 0.00317085 0.494771" mass="0.03" diaginertia="2.80077e-05 2.73576e-05 1.22613e-05" />
                <joint name="l_ankle_lateral_joint" pos="0 0 0" axis="0 0 -1" range="-0.8 0.8" actuatorfrcrange="-10 10" />
                <geom name="l_ankle_lateral_collision" size="0.02025 0.0145 0.0415" pos="-0.009 0 -0.016" type="box" rgba="0.2 0.2 0.2 0.1" group="2" />
                <geom name="l_foot_collision" size="0.0045 0.0305 0.0505" pos="-0.0277 0 0" type="box" rgba="0.2 0.2 0.2 0.1" group="2" />
              </body>
            </body>
          </body>
        </body>
      </body>
    </body>
  </worldbody>
  <asset>
    <mesh name="8b120736_BPF-CHEST-F_FCD-Conv_BDR-Col" file="8b120736_BPF-CHEST-F_FCD-Conv_BDR-Col.stl" scale="0.001 0.001 0.001" />
    <mesh name="94afeb60_BPF-CHEST-B_FCD-Conv_BDR-Col" file="94afeb60_BPF-CHEST-B_FCD-Conv_BDR-Col.stl" scale="0.001 0.001 0.001" />
    <mesh name="df1d2ef7_CM-5_FCD-Conv_BDR-Col" file="df1d2ef7_CM-5_FCD-Conv_BDR-Col.stl" scale="0.001 0.001 0.001" />
    <mesh name="2c813877_AX-S1_FCD-Conv_BDR-Col" file="2c813877_AX-S1_FCD-Conv_BDR-Col.stl" scale="0.001 0.001 0.001" />
    <mesh name="3c0b5d99_AX-12_FCD-Conv_BDR-Col" file="3c0b5d99_AX-12_FCD-Conv_BDR-Col.stl" scale="0.001 0.001 0.001" />
    <mesh name="d8612dc6_FP04-F3_FCD-Conv_BDR-Col" file="d8612dc6_FP04-F3_FCD-Conv_BDR-Col.stl" scale="0.001 0.001 0.001" />
    <mesh name="11c5acbd_FP04-F1_FCD-Conv_BDR-Col" file="11c5acbd_FP04-F1_FCD-Conv_BDR-Col.stl" scale="0.001 0.001 0.001" />
    <mesh name="5f501081_BPF-BU_FCD-Conv_BDR-Col" file="5f501081_BPF-BU_FCD-Conv_BDR-Col.stl" scale="0.001 0.001 0.001" />
    <mesh name="c9bc5e6a_BPF-WA_FCD-Conv_BDR-Col" file="c9bc5e6a_BPF-WA_FCD-Conv_BDR-Col.stl" scale="0.001 0.001 0.001" />
    <mesh name="b04d8bdf_FP04-F2_FCD-Conv_BDR-Col" file="b04d8bdf_FP04-F2_FCD-Conv_BDR-Col.stl" scale="0.001 0.001 0.001" />
    <mesh name="abc2df66_FP04-F11_FCD-Conv_BDR-Col" file="abc2df66_FP04-F11_FCD-Conv_BDR-Col.stl" scale="0.001 0.001 0.001" />
    <mesh name="df207a8e_FP04-F5_FCD-Conv_BDR-Col" file="df207a8e_FP04-F5_FCD-Conv_BDR-Col.stl" scale="0.001 0.001 0.001" />
    <mesh name="c44f3233_FP04-F6_FCD-Conv_BDR-Col" file="c44f3233_FP04-F6_FCD-Conv_BDR-Col.stl" scale="0.001 0.001 0.001" />
    <mesh name="4aa1180e_FP04-F7_FCD-Conv_BDR-Col" file="4aa1180e_FP04-F7_FCD-Conv_BDR-Col.stl" scale="0.001 0.001 0.001" />
    <mesh name="9856e80b_FP04-F4_FCD-Conv_BDR-Col" file="9856e80b_FP04-F4_FCD-Conv_BDR-Col.stl" scale="0.001 0.001 0.001" />
    <mesh name="bc9e07fb_FP04-F12_FCD-Conv_BDR-Col" file="bc9e07fb_FP04-F12_FCD-Conv_BDR-Col.stl" scale="0.001 0.001 0.001" />
    <mesh name="916d31db_Bioloid_CUERPO_vis_4" file="916d31db_Bioloid_CUERPO_vis_4.stl" scale="1.0 1.0 1.0" />
    <mesh name="fe3dec6d_Bioloid_CUERPO_vis_2" file="fe3dec6d_Bioloid_CUERPO_vis_2.stl" scale="1.0 1.0 1.0" />
  </asset>
  <default>
    <mesh scale="0.001 0.001 0.001" />
    <geom rgba="0.7 0.7 0.7 1.0" />
    <joint damping="0.5" frictionloss="0.03" />
    <default class="visual">
      <geom contype="0" conaffinity="0" group="1" />
    </default>
  </default>
</mujoco>
